Workbook

Sheet 2025 actual v budget
A1: Budget Detail by Month / Country / Product
A2: Month | B2: Country | C2: Product | D2: Actual_TPV_USD | E2: Budget_TPV_USD | F2: TPV_Var_$ | G2: TPV_Var_% | H2: Actual_Revenue_USD | I2: Budget_Revenue_USD | J2: Revenue_Var_$ | K2: Revenue_Var_% | L2: Actual_COGS_USD | M2: Budget_COGS_USD | N2: COGS_Var_$ | O2: COGS_Var_% | P2: Actual_Loss_Provision_USD | Q2: Budget_Loss_Provision_USD | R2: Loss_Provision_Var_$ | S2: Loss_Provision_Var_% | T2: Actual_Gross_Profit_USD | U2: Budget_Gross_Profit_USD | V2: Gross_Profit_Var_$ | W2: Gross_Profit_Var_% | X2: Actual_Operating_Expense_USD | Y2: Budget_Operating_Expense_USD | Z2: Opex_Var_$ | AA2: Opex_Var_% | AB2: Actual_Operating_Profit_USD | AC2: Budget_Operating_Profit_USD | AD2: Operating_Profit_Var_$ | AE2: Operating_Profit_Var_%
A3: Jan-25 | B3: Brazil | C3: Cross-border Payouts | D3: 10691718 | E3: 10247981 | F3: 443737.57 | G3: 0.0433 | H3: 80187.89 | I3: 76274.98 | J3: 3912.91 | K3: 0.0513 | L3: 28065.76 | M3: 26246.85 | N3: 1818.91 | O3: 0.0693 | P3: 1924.51 | Q3: 1783.11 | R3: 141.4 | S3: 0.0793 | T3: 50197.62 | U3: 47253.71 | V3: 2943.91 | W3: 0.0623 | X3: 33972.32 | Y3: 31652.21 | Z3: 2320.11 | AA3: 0.0733 | AB3: 16225.3 | AC3: 14800.06 | AD3: 1425.25 | AE3: 0.0963
A4: Jan-25 | B4: Brazil | C4: FX Conversion | D4: 16941176 | E4: 15742247 | F4: 1198929.5 | G4: 0.0762 | H4: 177882.35 | I4: 164073.89 | J4: 13808.46 | K4: 0.0842 | L4: 49807.06 | M4: 45190.41 | N4: 4616.65 | O4: 0.1022 | P4: 3049.41 | Q4: 2741.88 | R4: 307.53 | S4: 0.1122 | T4: 125025.88 | U4: 114162.2 | V4: 10863.68 | W4: 0.0952 | X4: 75361.45 | Y4: 68128.89 | Z4: 7232.56 | AA4: 0.1062 | AB4: 49664.43 | AC4: 43983.52 | AD4: 5680.91 | AE4: 0.1292
A5: Jan-25 | B5: Brazil | C5: Stablecoin Settlement | D5: 25621674 | E5: 24749502 | F5: 872172.45 | G5: 0.0352 | H5: 166540.88 | I5: 159638.13 | J5: 6902.75 | K5: 0.0432 | L5: 53293.08 | M5: 50217.75 | N5: 3075.33 | O5: 0.0612 | P5: 4611.9 | Q5: 4305.2 | R5: 306.7 | S5: 0.0712 | T5: 108635.9 | U5: 103046.65 | V5: 5589.25 | W5: 0.0542 | X5: 70556.54 | Y5: 66235.34 | Z5: 4321.19 | AA5: 0.0652 | AB5: 38079.36 | AC5: 34991.7 | AD5: 3087.67 | AE5: 0.0882
A6: Jan-25 | B6: Brazil | C6: Treasury Yield | D6: 7138685 | E6: 7439229.9 | F6: -300544.89 | G6: -0.0404 | H6: 21416.06 | I6: 22133.17 | J6: -717.11 | K6: -0.0324 | L6: 3854.89 | M6: 3911.21 | N6: -56.32 | O6: -0.0144 | P6: 1284.96 | Q6: 1290.64 | R6: -5.68 | S6: -0.0044 | T6: 16276.2 | U6: 16632.13 | V6: -355.93 | W6: -0.0214 | X6: 9073.11 | Y6: 9168.46 | Z6: -95.35 | AA6: -0.0104 | AB6: 7203.09 | AC6: 7113.46 | AD6: 89.63 | AE6: 0.0126
A7: Jan-25 | B7: Brazil | C7: Virtual Accounts | D7: 10439540 | E7: 10645206 | F7: -205665.37 | G7: -0.0193 | H7: 46977.93 | I7: 47515.81 | J7: -537.88 | K7: -0.0113 | L7: 10335.14 | M7: 10266.56 | N7: 68.58 | O7: 0.0067 | P7: 1879.12 | Q7: 1848.29 | R7: 30.83 | S7: 0.0167 | T7: 34763.67 | U7: 34774.8 | V7: -11.13 | W7: -0.0003 | X7: 19902.62 | Y7: 19692.31 | Z7: 210.31 | AA7: 0.0107 | AB7: 14861.05 | AC7: 14376.84 | AD7: 484.21 | AE7: 0.0337
A8: Jan-25 | B8: Germany | C8: Cross-border Payouts | D8: 5804075.8 | E8: 5753901.7 | F8: 50174.02 | G8: 0.0087 | H8: 43530.57 | I8: 42814.71 | J8: 715.86 | K8: 0.0167 | L8: 15235.7 | M8: 14724.47 | N8: 511.23 | O8: 0.0347 | P8: 522.37 | Q8: 500.01 | R8: 22.36 | S8: 0.0447 | T8: 27772.5 | U8: 27023.41 | V8: 749.09 | W8: 0.0277 | X8: 18442.12 | Y8: 17754.66 | Z8: 687.46 | AA8: 0.0387 | AB8: 9330.38 | AC8: 8787.99 | AD8: 542.39 | AE8: 0.0617
A9: Jan-25 | B9: Germany | C9: FX Conversion | D9: 9196638.5 | E9: 8829507.6 | F9: 367130.92 | G9: 0.0416 | H9: 96564.7 | I9: 92003.18 | J9: 4561.52 | K9: 0.0496 | L9: 27038.12 | M9: 25326.55 | N9: 1711.57 | O9: 0.0676 | P9: 827.7 | Q9: 768.11 | R9: 59.59 | S9: 0.0776 | T9: 68698.89 | U9: 64774.83 | V9: 3924.06 | W9: 0.0606 | X9: 40910.5 | Y9: 38177.74 | Z9: 2732.76 | AA9: 0.0716 | AB9: 27788.39 | AC9: 25387.26 | AD9: 2401.13 | AE9: 0.0946
A10: Jan-25 | B10: Germany | C10: Stablecoin Settlement | D10: 13908909 | E10: 13899735 | F10: 9173.83 | G10: 0.0007 | H10: 90407.91 | I10: 89631.7 | J10: 776.21 | K10: 0.0087 | L10: 28930.53 | M10: 28179.27 | N10: 751.26 | O10: 0.0267 | P10: 1251.8 | Q10: 1207.53 | R10: 44.27 | S10: 0.0367 | T10: 60225.58 | U10: 59064.37 | V10: 1161.21 | W10: 0.0197 | X10: 38302.12 | Y10: 37162.71 | Z10: 1139.41 | AA10: 0.0307 | AB10: 21923.46 | AC10: 20806.96 | AD10: 1116.5 | AE10: 0.0537
A11: Jan-25 | B11: Germany | C11: Treasury Yield | D11: 3875286.2 | E11: 4189408 | F11: -314121.81 | G11: -0.075 | H11: 11625.86 | I11: 12460.46 | J11: -834.6 | K11: -0.067 | L11: 2092.65 | M11: 2200.43 | N11: -107.78 | O11: -0.049 | P11: 348.78 | Q11: 362.93 | R11: -14.15 | S11: -0.039 | T11: 9184.43 | U11: 9729.06 | V11: -544.63 | W11: -0.056 | X11: 4925.4 | Y11: 5157.38 | Z11: -231.98 | AA11: -0.045 | AB11: 4259.03 | AC11: 4354.75 | AD11: -95.72 | AE11: -0.022
A12: Jan-25 | B12: Germany | C12: Virtual Accounts | D12: 5667179 | E12: 5990042.3 | F12: -322863.28 | G12: -0.0539 | H12: 25502.31 | I12: 26729.18 | J12: -1226.87 | K12: -0.0459 | L12: 5610.51 | M12: 5771.54 | N12: -161.03 | O12: -0.0279 | P12: 510.05 | Q12: 519.35 | R12: -9.3 | S12: -0.0179 | T12: 19381.75 | U12: 20082.63 | V12: -700.88 | W12: -0.0349 | X12: 10804.28 | Y12: 11068.83 | Z12: -264.54 | AA12: -0.0239 | AB12: 8577.47 | AC12: 8585.19 | AD12: -7.73 | AE12: -0.0009
A13: Jan-25 | B13: India | C13: Cross-border Payouts | D13: 6873247.6 | E13: 6653418.7 | F13: 219828.95 | G13: 0.033 | H13: 51549.36 | I13: 49517.18 | J13: 2032.18 | K13: 0.041 | L13: 18042.27 | M13: 17036.44 | N13: 1005.83 | O13: 0.059 | P13: 1374.65 | Q13: 1285.87 | R13: 88.78 | S13: 0.069 | T13: 32132.43 | U13: 30542.97 | V13: 1589.46 | W13: 0.052 | X13: 21839.35 | Y13: 20544.24 | Z13: 1295.11 | AA13: 0.063 | AB13: 10293.08 | AC13: 9477.63 | AD13: 815.45 | AE13: 0.086
A14: Jan-25 | B14: India | C14: FX Conversion | D14: 10890756 | E14: 10217428 | F14: 673328.48 | G14: 0.0659 | H14: 114352.94 | I14: 106483.79 | J14: 7869.15 | K14: 0.0739 | L14: 32018.82 | M14: 29323.95 | N14: 2694.87 | O14: 0.0919 | P14: 2178.15 | Q14: 1976.72 | R14: 201.43 | S14: 0.1019 | T14: 80155.96 | U14: 73883.27 | V14: 6272.69 | W14: 0.0849 | X14: 48446.65 | Y14: 44207.18 | Z14: 4239.47 | AA14: 0.0959 | AB14: 31709.31 | AC14: 28339.72 | AD14: 3369.59 | AE14: 0.1189
... A362: Dec-25 | B362: USA | C362: Virtual Accounts | D362: 29770096 | E362: 26787086 | F362: 2983009.9 | G362: 0.1114 | H362: 133965.43 | I362: 119680.38 | J362: 14285.05 | K362: 0.1194 | L362: 29472.39 | M362: 25912.98 | N362: 3559.41 | O362: 0.1374 | P362: 2083.91 | Q362: 1816.27 | R362: 267.64 | S362: 0.1474 | T362: 102409.13 | U362: 90598.69 | V362: 11810.44 | W362: 0.1304 | X362: 52704.3 | Y362: 46176.76 | Z362: 6527.55 | AA362: 0.1414 | AB362: 49704.83 | AC362: 42688.54 | AD362: 7016.29 | AE362: 0.1644
A364: Total 2025 | B364: Brazil | C364: Cross-border Payouts | D364: =D3+D33+D63+D93+D123+D153+D183+D213+D243+D273+D303+D333 -> 1.8210698e+08 | E364: =E3+E33+E63+E93+E123+E153+E183+E213+E243+E273+E303+E333 -> 1.7602308e+08 | F364: =F3+F33+F63+F93+F123+F153+F183+F213+F243+F273+F303+F333 -> 6083905.1 | G364: =F364/E364 -> 0.03456311 | H364: =H3+H33+H63+H93+H123+H153+H183+H213+H243+H273+H303+H333 -> 1365802.4 | I364: =I3+I33+I63+I93+I123+I153+I183+I213+I243+I273+I303+I333 -> 1310015.2 | J364: =J3+J33+J63+J93+J123+J153+J183+J213+J243+J273+J303+J333 -> 55787.22 | K364: =J364/I364 -> 0.042585171 | L364: =L3+L33+L63+L93+L123+L153+L183+L213+L243+L273+L303+L333 -> 478030.83 | M364: =M3+M33+M63+M93+M123+M153+M183+M213+M243+M273+M303+M333 -> 450703.1 | N364: =N3+N33+N63+N93+N123+N153+N183+N213+N243+N273+N303+N333 -> 27327.73 | O364: =N364/M364 -> 0.060633552 | P364: =P3+P33+P63+P93+P123+P153+P183+P213+P243+P273+P303+P333 -> 32779.25 | Q364: =Q3+Q33+Q63+Q93+Q123+Q153+Q183+Q213+Q243+Q273+Q303+Q333 -> 30615.93 | R364: =R3+R33+R63+R93+R123+R153+R183+R213+R243+R273+R303+R333 -> 2163.32 | S364: =R364/Q364 -> 0.070659947 | T364: =T3+T33+T63+T93+T123+T153+T183+T213+T243+T273+T303+T333 -> 854992.31 | U364: =U3+U33+U63+U93+U123+U153+U183+U213+U243+U273+U303+U333 -> 811484.64 | V364: =V3+V33+V63+V93+V123+V153+V183+V213+V243+V273+V303+V333 -> 43507.67 | W364: =V364/U364 -> 0.053614903 | X364: =X3+X33+X63+X93+X123+X153+X183+X213+X243+X273+X303+X333 -> 565863.18 | Y364: =Y3+Y33+Y63+Y93+Y123+Y153+Y183+Y213+Y243+Y273+Y303+Y333 -> 531349.68 | Z364: =Z3+Z33+Z63+Z93+Z123+Z153+Z183+Z213+Z243+Z273+Z303+Z333 -> 34513.51 | AA364: =Z364/Y364 -> 0.064954419 | AB364: =AB3+AB33+AB63+AB93+AB123+AB153+AB183+AB213+AB243+AB273+AB303+AB333 -> 289129.13 | AC364: =AC3+AC33+AC63+AC93+AC123+AC153+AC183+AC213+AC243+AC273+AC303+AC333 -> 265964.31 | AD364: =AD3+AD33+AD63+AD93+AD123+AD153+AD183+AD213+AD243+AD273+AD303+AD333 -> 23164.82 | AE364: =AD364/AC364 -> 0.087097476
B365: Brazil | C365: FX Conversion | D365: =D4+D34+D64+D94+D124+D154+D184+D214+D244+D274+D304+D334 -> 2.8318271e+08 | E365: =E4+E34+E64+E94+E124+E154+E184+E214+E244+E274+E304+E334 -> 2.6919199e+08 | F365: =F4+F34+F64+F94+F124+F154+F184+F214+F244+F274+F304+F334 -> 13990716 | G365: =F365/E365 -> 0.051973004 | H365: =H4+H34+H64+H94+H124+H154+H184+H214+H244+H274+H304+H334 -> 2973418.4 | I365: =I4+I34+I64+I94+I124+I154+I184+I214+I244+I274+I304+I334 -> 2805136.6 | J365: =J4+J34+J64+J94+J124+J154+J184+J214+J244+J274+J304+J334 -> 168281.8 | K365: =J365/I365 -> 0.059990589 | L365: =L4+L34+L64+L94+L124+L154+L184+L214+L244+L274+L304+L334 -> 832557.17 | M365: =M4+M34+M64+M94+M124+M154+M184+M214+M244+M274+M304+M334 -> 772295.54 | N365: =N4+N34+N64+N94+N124+N154+N184+N214+N244+N274+N304+N334 -> 60261.63 | O365: =N365/M365 -> 0.078029235 | P365: =P4+P34+P64+P94+P124+P154+P184+P214+P244+P274+P304+P334 -> 50972.89 | Q365: =Q4+Q34+Q64+Q94+Q124+Q154+Q184+Q214+Q244+Q274+Q304+Q334 -> 46847.91 | R365: =R4+R34+R64+R94+R124+R154+R184+R214+R244+R274+R304+R334 -> 4124.98 | S365: =R365/Q365 -> 0.088050459 | T365: =T4+T34+T64+T94+T124+T154+T184+T214+T244+T274+T304+T334 -> 2089888.4 | U365: =U4+U34+U64+U94+U124+U154+U184+U214+U244+U274+U304+U334 -> 1951316.9 | V365: =V4+V34+V64+V94+V124+V154+V184+V214+V244+V274+V304+V334 -> 138571.49 | W365: =V365/U365 -> 0.071014345 | X365: =X4+X34+X64+X94+X124+X154+X184+X214+X244+X274+X304+X334 -> 1232122.5 | Y365: =Y4+Y34+Y64+Y94+Y124+Y154+Y184+Y214+Y244+Y274+Y304+Y334 -> 1138910.9 | Z365: =Z4+Z34+Z64+Z94+Z124+Z154+Z184+Z214+Z244+Z274+Z304+Z334 -> 93211.6 | AA365: =Z365/Y365 -> 0.081842747 | AB365: =AB4+AB34+AB64+AB94+AB124+AB154+AB184+AB214+AB244+AB274+AB304+AB334 -> 857765.84 | AC365: =AC4+AC34+AC64+AC94+AC124+AC154+AC184+AC214+AC244+AC274+AC304+AC334 -> 776001.95 | AD365: =AD4+AD34+AD64+AD94+AD124+AD154+AD184+AD214+AD244+AD274+AD304+AD334 -> 81763.88 | AE365: =AD365/AC365 -> 0.10536556
B366: Brazil | C366: Stablecoin Settlement | D366: =D5+D35+D65+D95+D125+D155+D185+D215+D245+D275+D305+D335 -> 4.3722214e+08 | E366: =E5+E35+E65+E95+E125+E155+E185+E215+E245+E275+E305+E335 -> 4.2248255e+08 | F366: =F5+F35+F65+F95+F125+F155+F185+F215+F245+F275+F305+F335 -> 14739592 | G366: =F366/E366 -> 0.034888049 | H366: =H5+H35+H65+H95+H125+H155+H185+H215+H245+H275+H305+H335 -> 2841943.9 | I366: =I5+I35+I65+I95+I125+I155+I185+I215+I245+I275+I305+I335 -> 2724999.5 | J366: =J5+J35+J65+J95+J125+J155+J185+J215+J245+J275+J305+J335 -> 116944.42 | K366: =J366/I366 -> 0.042915392 | L366: =L5+L35+L65+L95+L125+L155+L185+L215+L245+L275+L305+L335 -> 909422.06 | M366: =M5+M35+M65+M95+M125+M155+M185+M215+M245+M275+M305+M335 -> 857156.61 | N366: =N5+N35+N65+N95+N125+N155+N185+N215+N245+N275+N305+N335 -> 52265.45 | O366: =N366/M366 -> 0.06097538 | P366: =P5+P35+P65+P95+P125+P155+P185+P215+P245+P275+P305+P335 -> 78699.96 | Q366: =Q5+Q35+Q65+Q95+Q125+Q155+Q185+Q215+Q245+Q275+Q305+Q335 -> 73482.15 | R366: =R5+R35+R65+R95+R125+R155+R185+R215+R245+R275+R305+R335 -> 5217.81 | S366: =R366/Q366 -> 0.071007857 | T366: =T5+T35+T65+T95+T125+T155+T185+T215+T245+T275+T305+T335 -> 1853821.9 | U366: =U5+U35+U65+U95+U125+U155+U185+U215+U245+U275+U305+U335 -> 1758923.9 | V366: =V5+V35+V65+V95+V125+V155+V185+V215+V245+V275+V305+V335 -> 94897.98 | W366: =V366/U366 -> 0.053952295 | X366: =X5+X35+X65+X95+X125+X155+X185+X215+X245+X275+X305+X335 -> 1177413.5 | Y366: =Y5+Y35+Y65+Y95+Y125+Y155+Y185+Y215+Y245+Y275+Y305+Y335 -> 1105107.9 | Z366: =Z5+Z35+Z65+Z95+Z125+Z155+Z185+Z215+Z245+Z275+Z305+Z335 -> 72305.52 | AA366: =Z366/Y366 -> 0.065428469 | AB366: =AB5+AB35+AB65+AB95+AB125+AB155+AB185+AB215+AB245+AB275+AB305+AB335 -> 676408.37 | AC366: =AC5+AC35+AC65+AC95+AC125+AC155+AC185+AC215+AC245+AC275+AC305+AC335 -> 622100.7 | AD366: =AD5+AD35+AD65+AD95+AD125+AD155+AD185+AD215+AD245+AD275+AD305+AD335 -> 54307.69 | AE366: =AD366/AC366 -> 0.087297266
B367: Brazil | C367: Treasury Yield | D367: =D6+D36+D66+D96+D126+D156+D186+D216+D246+D276+D306+D336 -> 1.1790761e+08 | E367: =E6+E36+E66+E96+E126+E156+E186+E216+E246+E276+E306+E336 -> 1.1478833e+08 | F367: =F6+F36+F66+F96+F126+F156+F186+F216+F246+F276+F306+F336 -> 3119271.7 | G367: =F367/E367 -> 0.027174118 | H367: =H6+H36+H66+H96+H126+H156+H186+H216+H246+H276+H306+H336 -> 353722.82 | I367: =I6+I36+I66+I96+I126+I156+I186+I216+I246+I276+I306+I336 -> 341699.56 | J367: =J6+J36+J66+J96+J126+J156+J186+J216+J246+J276+J306+J336 -> 12023.26 | K367: =J367/I367 -> 0.035186642 | L367: =L6+L36+L66+L96+L126+L156+L186+L216+L246+L276+L306+L336 -> 63670.12 | M367: =M6+M36+M66+M96+M126+M156+M186+M216+M246+M276+M306+M336 -> 60453.15 | N367: =N6+N36+N66+N96+N126+N156+N186+N216+N246+N276+N306+N336 -> 3216.97 | O367: =N367/M367 -> 0.053214266 | P367: =P6+P36+P66+P96+P126+P156+P186+P216+P246+P276+P306+P336 -> 21223.37 | Q367: =Q6+Q36+Q66+Q96+Q126+Q156+Q186+Q216+Q246+Q276+Q306+Q336 -> 19961.25 | R367: =R6+R36+R66+R96+R126+R156+R186+R216+R246+R276+R306+R336 -> 1262.12 | S367: =R367/Q367 -> 0.063228505 | T367: =T6+T36+T66+T96+T126+T156+T186+T216+T246+T276+T306+T336 -> 268829.35 | U367: =U6+U36+U66+U96+U126+U156+U186+U216+U246+U276+U306+U336 -> 256957.03 | V367: =V6+V36+V66+V96+V126+V156+V186+V216+V246+V276+V306+V336 -> 11872.32 | W367: =V367/U367 -> 0.046203523 | X367: =X6+X36+X66+X96+X126+X156+X186+X216+X246+X276+X306+X336 -> 146564.63 | Y367: =Y6+Y36+Y66+Y96+Y126+Y156+Y186+Y216+Y246+Y276+Y306+Y336 -> 138658.15 | Z367: =Z6+Z36+Z66+Z96+Z126+Z156+Z186+Z216+Z246+Z276+Z306+Z336 -> 7906.48 | AA367: =Z367/Y367 -> 0.057021387 | AB367: =AB6+AB36+AB66+AB96+AB126+AB156+AB186+AB216+AB246+AB276+AB306+AB336 -> 122264.72 | AC367: =AC6+AC36+AC66+AC96+AC126+AC156+AC186+AC216+AC246+AC276+AC306+AC336 -> 113156.54 | AD367: =AD6+AD36+AD66+AD96+AD126+AD156+AD186+AD216+AD246+AD276+AD306+AD336 -> 9108.2 | AE367: =AD367/AC367 -> 0.080492033
B368: Brazil | C368: Virtual Accounts | D368: =D7+D37+D67+D97+D127+D157+D187+D217+D247+D277+D307+D337 -> 1.772455e+08 | E368: =E7+E37+E67+E97+E127+E157+E187+E217+E247+E277+E307+E337 -> 1.7202165e+08 | F368: =F7+F37+F67+F97+F127+F157+F187+F217+F247+F277+F307+F337 -> 5223845.9 | G368: =F368/E368 -> 0.030367374 | H368: =H7+H37+H67+H97+H127+H157+H187+H217+H247+H277+H307+H337 -> 797604.72 | I368: =I7+I37+I67+I97+I127+I157+I187+I217+I247+I277+I307+I337 -> 768125.52 | J368: =J7+J37+J67+J97+J127+J157+J187+J217+J247+J277+J307+J337 -> 29479.2 | K368: =J368/I368 -> 0.038378103 | L368: =L7+L37+L67+L97+L127+L157+L187+L217+L247+L277+L307+L337 -> 175473.04 | M368: =M7+M37+M67+M97+M127+M157+M187+M217+M247+M277+M307+M337 -> 166104.45 | N368: =N7+N37+N67+N97+N127+N157+N187+N217+N247+N277+N307+N337 -> 9368.59 | O368: =N368/M368 -> 0.0564018 | P368: =P7+P37+P67+P97+P127+P157+P187+P217+P247+P277+P307+P337 -> 31904.19 | Q368: =Q7+Q37+Q67+Q97+Q127+Q157+Q187+Q217+Q247+Q277+Q307+Q337 -> 29917.25 | R368: =R7+R37+R67+R97+R127+R157+R187+R217+R247+R277+R307+R337 -> 1986.94 | S368: =R368/Q368 -> 0.066414527 | T368: =T7+T37+T67+T97+T127+T157+T187+T217+T247+T277+T307+T337 -> 590227.5 | U368: =U7+U37+U67+U97+U127+U157+U187+U217+U247+U277+U307+U337 -> 562446.79 | V368: =V7+V37+V67+V97+V127+V157+V187+V217+V247+V277+V307+V337 -> 27780.71 | W368: =V368/U368 -> 0.049392601 | X368: =X7+X37+X67+X97+X127+X157+X187+X217+X247+X277+X307+X337 -> 330516 | Y368: =Y7+Y37+Y67+Y97+Y127+Y157+Y187+Y217+Y247+Y277+Y307+Y337 -> 311764.71 | Z368: =Z7+Z37+Z67+Z97+Z127+Z157+Z187+Z217+Z247+Z277+Z307+Z337 -> 18751.25 | AA368: =Z368/Y368 -> 0.060145518 | AB368: =AB7+AB37+AB67+AB97+AB127+AB157+AB187+AB217+AB247+AB277+AB307+AB337 -> 259711.5 | AC368: =AC7+AC37+AC67+AC97+AC127+AC157+AC187+AC217+AC247+AC277+AC307+AC337 -> 239637.24 | AD368: =AD7+AD37+AD67+AD97+AD127+AD157+AD187+AD217+AD247+AD277+AD307+AD337 -> 20074.28 | AE368: =AD368/AC368 -> 0.083769451
B369: Germany | C369: Cross-border Payouts | D369: =D8+D38+D68+D98+D128+D158+D188+D218+D248+D278+D308+D338 -> 88039025 | E369: =E8+E38+E68+E98+E128+E158+E188+E218+E248+E278+E308+E338 -> 86102105 | F369: =F8+F38+F68+F98+F128+F158+F188+F218+F248+F278+F308+F338 -> 1936919.2 | G369: =F369/E369 -> 0.022495608 | H369: =H8+H38+H68+H98+H128+H158+H188+H218+H248+H278+H308+H338 -> 660292.69 | I369: =I8+I38+I68+I98+I128+I158+I188+I218+I248+I278+I308+I338 -> 640743.91 | J369: =J8+J38+J68+J98+J128+J158+J188+J218+J248+J278+J308+J338 -> 19548.78 | K369: =J369/I369 -> 0.030509506 | L369: =L8+L38+L68+L98+L128+L158+L188+L218+L248+L278+L308+L338 -> 231102.44 | M369: =M8+M38+M68+M98+M128+M158+M188+M218+M248+M278+M308+M338 -> 220404.04 | N369: =N8+N38+N68+N98+N128+N158+N188+N218+N248+N278+N308+N338 -> 10698.4 | O369: =N369/M369 -> 0.048539945 | P369: =P8+P38+P68+P98+P128+P158+P188+P218+P248+P278+P308+P338 -> 7923.53 | Q369: =Q8+Q38+Q68+Q98+Q128+Q158+Q188+Q218+Q248+Q278+Q308+Q338 -> 7485.23 | R369: =R8+R38+R68+R98+R128+R158+R188+R218+R248+R278+R308+R338 -> 438.3 | S369: =R369/Q369 -> 0.058555315 | T369: =T8+T38+T68+T98+T128+T158+T188+T218+T248+T278+T308+T338 -> 421266.73 | U369: =U8+U38+U68+U98+U128+U158+U188+U218+U248+U278+U308+U338 -> 404469.81 | V369: =V8+V38+V68+V98+V128+V158+V188+V218+V248+V278+V308+V338 -> 16796.92 | W369: =V369/U369 -> 0.041528242 | X369: =X8+X38+X68+X98+X128+X158+X188+X218+X248+X278+X308+X338 -> 273683.59 | Y369: =Y8+Y38+Y68+Y98+Y128+Y158+Y188+Y218+Y248+Y278+Y308+Y338 -> 259974.91 | Z369: =Z8+Z38+Z68+Z98+Z128+Z158+Z188+Z218+Z248+Z278+Z308+Z338 -> 13708.67 | AA369: =Z369/Y369 -> 0.052730742 | AB369: =AB8+AB38+AB68+AB98+AB128+AB158+AB188+AB218+AB248+AB278+AB308+AB338 -> 147583.14 | AC369: =AC8+AC38+AC68+AC98+AC128+AC158+AC188+AC218+AC248+AC278+AC308+AC338 -> 137255.61 | AD369: =AD8+AD38+AD68+AD98+AD128+AD158+AD188+AD218+AD248+AD278+AD308+AD338 -> 10327.51 | AE369: =AD369/AC369 -> 0.075242899
B370: Germany | C370: FX Conversion | D370: =D9+D39+D69+D99+D129+D159+D189+D219+D249+D279+D309+D339 -> 1.3697483e+08 | E370: =E9+E39+E69+E99+E129+E159+E189+E219+E249+E279+E309+E339 -> 1.3178718e+08 | F370: =F9+F39+F69+F99+F129+F159+F189+F219+F249+F279+F309+F339 -> 5187652.4 | G370: =F370/E370 -> 0.039363862 | H370: =H9+H39+H69+H99+H129+H159+H189+H219+H249+H279+H309+H339 -> 1438235.7 | I370: =I9+I39+I69+I99+I129+I159+I189+I219+I249+I279+I309+I339 -> 1373179.3 | J370: =J9+J39+J69+J99+J129+J159+J189+J219+J249+J279+J309+J339 -> 65056.43 | K370: =J370/I370 -> 0.0473765 | L370: =L9+L39+L69+L99+L129+L159+L189+L219+L249+L279+L309+L339 -> 402706.01 | M370: =M9+M39+M69+M99+M129+M159+M189+M219+M249+M279+M309+M339 -> 377984.23 | N370: =N9+N39+N69+N99+N129+N159+N189+N219+N249+N279+N309+N339 -> 24721.78 | O370: =N370/M370 -> 0.065404263 | P370: =P9+P39+P69+P99+P129+P159+P189+P219+P249+P279+P309+P339 -> 12327.74 | Q370: =Q9+Q39+Q69+Q99+Q129+Q159+Q189+Q219+Q249+Q279+Q309+Q339 -> 11463.18 | R370: =R9+R39+R69+R99+R129+R159+R189+R219+R249+R279+R309+R339 -> 864.56 | S370: =R370/Q370 -> 0.075420608 | T370: =T9+T39+T69+T99+T129+T159+T189+T219+T249+T279+T309+T339 -> 1023202 | U370: =U9+U39+U69+U99+U129+U159+U189+U219+U249+U279+U309+U339 -> 966750.02 | V370: =V9+V39+V69+V99+V129+V159+V189+V219+V249+V279+V309+V339 -> 56451.98 | W370: =V370/U370 -> 0.058393565 | X370: =X9+X39+X69+X99+X129+X159+X189+X219+X249+X279+X309+X339 -> 596222.14 | Y370: =Y9+Y39+Y69+Y99+Y129+Y159+Y189+Y219+Y249+Y279+Y309+Y339 -> 557688.31 | Z370: =Z9+Z39+Z69+Z99+Z129+Z159+Z189+Z219+Z249+Z279+Z309+Z339 -> 38533.82 | AA370: =Z370/Y370 -> 0.069095621 | AB370: =AB9+AB39+AB69+AB99+AB129+AB159+AB189+AB219+AB249+AB279+AB309+AB339 -> 426979.86 | AC370: =AC9+AC39+AC69+AC99+AC129+AC159+AC189+AC219+AC249+AC279+AC309+AC339 -> 390690.9 | AD370: =AD9+AD39+AD69+AD99+AD129+AD159+AD189+AD219+AD249+AD279+AD309+AD339 -> 36288.96 | AE370: =AD370/AC370 -> 0.092884068
B371: Germany | C371: Stablecoin Settlement | D371: =D10+D40+D70+D100+D130+D160+D190+D220+D250+D280+D310+D340 -> 2.1131042e+08 | E371: =E10+E40+E70+E100+E130+E160+E190+E220+E250+E280+E310+E340 -> 2.0666587e+08 | F371: =F10+F40+F70+F100+F130+F160+F190+F220+F250+F280+F310+F340 -> 4644555.5 | G371: =F371/E371 -> 0.022473743 | H371: =H10+H40+H70+H100+H130+H160+H190+H220+H250+H280+H310+H340 -> 1373517.8 | I371: =I10+I40+I70+I100+I130+I160+I190+I220+I250+I280+I310+I340 -> 1332874.4 | J371: =J10+J40+J70+J100+J130+J160+J190+J220+J250+J280+J310+J340 -> 40643.4 | K371: =J371/I371 -> 0.030493046 | L371: =L10+L40+L70+L100+L130+L160+L190+L220+L250+L280+L310+L340 -> 439525.68 | M371: =M10+M40+M70+M100+M130+M160+M190+M220+M250+M280+M310+M340 -> 419180.58 | N371: =N10+N40+N70+N100+N130+N160+N190+N220+N250+N280+N310+N340 -> 20345.1 | O371: =N371/M371 -> 0.048535407 | P371: =P10+P40+P70+P100+P130+P160+P190+P220+P250+P280+P310+P340 -> 19017.94 | Q371: =Q10+Q40+Q70+Q100+Q130+Q160+Q190+Q220+Q250+Q280+Q310+Q340 -> 17965.91 | R371: =R10+R40+R70+R100+R130+R160+R190+R220+R250+R280+R310+R340 -> 1052.03 | S371: =R371/Q371 -> 0.058557012 | T371: =T10+T40+T70+T100+T130+T160+T190+T220+T250+T280+T310+T340 -> 914974.15 | U371: =U10+U40+U70+U100+U130+U160+U190+U220+U250+U280+U310+U340 -> 878499.64 | V371: =V10+V40+V70+V100+V130+V160+V190+V220+V250+V280+V310+V340 -> 36474.51 | W371: =V371/U371 -> 0.041519095 | X371: =X10+X40+X70+X100+X130+X160+X190+X220+X250+X280+X310+X340 -> 569305 | Y371: =Y10+Y40+Y70+Y100+Y130+Y160+Y190+Y220+Y250+Y280+Y310+Y340 -> 540716.3 | Z371: =Z10+Z40+Z70+Z100+Z130+Z160+Z190+Z220+Z250+Z280+Z310+Z340 -> 28588.68 | AA371: =Z371/Y371 -> 0.052871866 | AB371: =AB10+AB40+AB70+AB100+AB130+AB160+AB190+AB220+AB250+AB280+AB310+AB340 -> 345669.15 | AC371: =AC10+AC40+AC70+AC100+AC130+AC160+AC190+AC220+AC250+AC280+AC310+AC340 -> 321535.42 | AD371: =AD10+AD40+AD70+AD100+AD130+AD160+AD190+AD220+AD250+AD280+AD310+AD340 -> 24133.72 | AE371: =AD371/AC371 -> 0.075057734
B372: Germany | C372: Treasury Yield | D372: =D11+D41+D71+D101+D131+D161+D191+D221+D251+D281+D311+D341 -> 57027627 | E372: =E11+E41+E71+E101+E131+E161+E191+E221+E251+E281+E311+E341 -> 56251159 | F372: =F11+F41+F71+F101+F131+F161+F191+F221+F251+F281+F311+F341 -> 776467.94 | G372: =F372/E372 -> 0.01380359 | H372: =H11+H41+H71+H101+H131+H161+H191+H221+H251+H281+H311+H341 -> 171082.89 | I372: =I11+I41+I71+I101+I131+I161+I191+I221+I251+I281+I311+I341 -> 167429.91 | J372: =J11+J41+J71+J101+J131+J161+J191+J221+J251+J281+J311+J341 -> 3652.98 | K372: =J372/I372 -> 0.021817965 | L372: =L11+L41+L71+L101+L131+L161+L191+L221+L251+L281+L311+L341 -> 30794.93 | M372: =M11+M41+M71+M101+M131+M161+M191+M221+M251+M281+M311+M341 -> 29614.78 | N372: =N11+N41+N71+N101+N131+N161+N191+N221+N251+N281+N311+N341 -> 1180.15 | O372: =N372/M372 -> 0.039850034 | P372: =P11+P41+P71+P101+P131+P161+P191+P221+P251+P281+P311+P341 -> 5132.49 | Q372: =Q11+Q41+Q71+Q101+Q131+Q161+Q191+Q221+Q251+Q281+Q311+Q341 -> 4888.71 | R372: =R11+R41+R71+R101+R131+R161+R191+R221+R251+R281+R311+R341 -> 243.78 | S372: =R372/Q372 -> 0.049865916 | T372: =T11+T41+T71+T101+T131+T161+T191+T221+T251+T281+T311+T341 -> 135155.47 | U372: =U11+U41+U71+U101+U131+U161+U191+U221+U251+U281+U311+U341 -> 130858.41 | V372: =V11+V41+V71+V101+V131+V161+V191+V221+V251+V281+V311+V341 -> 4297.06 | W372: =V372/U372 -> 0.032837477 | X372: =X11+X41+X71+X101+X131+X161+X191+X221+X251+X281+X311+X341 -> 70918.47 | Y372: =Y11+Y41+Y71+Y101+Y131+Y161+Y191+Y221+Y251+Y281+Y311+Y341 -> 67964.73 | Z372: =Z11+Z41+Z71+Z101+Z131+Z161+Z191+Z221+Z251+Z281+Z311+Z341 -> 2953.73 | AA372: =Z372/Y372 -> 0.043459747 | AB372: =AB11+AB41+AB71+AB101+AB131+AB161+AB191+AB221+AB251+AB281+AB311+AB341 -> 64237 | AC372: =AC11+AC41+AC71+AC101+AC131+AC161+AC191+AC221+AC251+AC281+AC311+AC341 -> 60184.62 | AD372: =AD11+AD41+AD71+AD101+AD131+AD161+AD191+AD221+AD251+AD281+AD311+AD341 -> 4052.38 | AE372: =AD372/AC372 -> 0.067332485
B373: Germany | C373: Virtual Accounts | D373: =D12+D42+D72+D102+D132+D162+D192+D222+D252+D282+D312+D342 -> 85670242 | E373: =E12+E42+E72+E102+E132+E162+E192+E222+E252+E282+E312+E342 -> 84244368 | F373: =F12+F42+F72+F102+F132+F162+F192+F222+F252+F282+F312+F342 -> 1425874.7 | G373: =F373/E373 -> 0.01692546 | H373: =H12+H42+H72+H102+H132+H162+H192+H222+H252+H282+H312+H342 -> 385516.1 | I373: =I12+I42+I72+I102+I132+I162+I192+I222+I252+I282+I312+I342 -> 376136.85 | J373: =J12+J42+J72+J102+J132+J162+J192+J222+J252+J282+J312+J342 -> 9379.25 | K373: =J373/I373 -> 0.024935738 | L373: =L12+L42+L72+L102+L132+L162+L192+L222+L252+L282+L312+L342 -> 84813.54 | M373: =M12+M42+M72+M102+M132+M162+M192+M222+M252+M282+M312+M342 -> 81320.15 | N373: =N12+N42+N72+N102+N132+N162+N192+N222+N252+N282+N312+N342 -> 3493.39 | O373: =N373/M373 -> 0.04295848 | P373: =P12+P42+P72+P102+P132+P162+P192+P222+P252+P282+P312+P342 -> 7710.34 | Q373: =Q12+Q42+Q72+Q102+Q132+Q162+Q192+Q222+Q252+Q282+Q312+Q342 -> 7322.47 | R373: =R12+R42+R72+R102+R132+R162+R192+R222+R252+R282+R312+R342 -> 387.87 | S373: =R373/Q373 -> 0.052969831 | T373: =T12+T42+T72+T102+T132+T162+T192+T222+T252+T282+T312+T342 -> 292992.24 | U373: =U12+U42+U72+U102+U132+U162+U192+U222+U252+U282+U312+U342 -> 282824.78 | V373: =V12+V42+V72+V102+V132+V162+V192+V222+V252+V282+V312+V342 -> 10167.46 | W373: =V373/U373 -> 0.035949679 | X373: =X12+X42+X72+X102+X132+X162+X192+X222+X252+X282+X312+X342 -> 159824.85 | Y373: =Y12+Y42+Y72+Y102+Y132+Y162+Y192+Y222+Y252+Y282+Y312+Y342 -> 152718.15 | Z373: =Z12+Z42+Z72+Z102+Z132+Z162+Z192+Z222+Z252+Z282+Z312+Z342 -> 7106.69 | AA373: =Z373/Y373 -> 0.046534678 | AB373: =AB12+AB42+AB72+AB102+AB132+AB162+AB192+AB222+AB252+AB282+AB312+AB342 -> 133167.39 | AC373: =AC12+AC42+AC72+AC102+AC132+AC162+AC192+AC222+AC252+AC282+AC312+AC342 -> 124396.7 | AD373: =AD12+AD42+AD72+AD102+AD132+AD162+AD192+AD222+AD252+AD282+AD312+AD342 -> 8770.68 | AE373: =AD373/AC373 -> 0.070505729
B374: India | C374: Cross-border Payouts | D374: =D13+D43+D73+D103+D133+D163+D193+D223+D253+D283+D313+D343 -> 1.2414339e+08 | E374: =E13+E43+E73+E103+E133+E163+E193+E223+E253+E283+E313+E343 -> 1.2060741e+08 | F374: =F13+F43+F73+F103+F133+F163+F193+F223+F253+F283+F313+F343 -> 3535980.1 | G374: =F374/E374 -> 0.0293181 | H374: =H13+H43+H73+H103+H133+H163+H193+H223+H253+H283+H313+H343 -> 931075.43 | I374: =I13+I43+I73+I103+I133+I163+I193+I223+I253+I283+I313+I343 -> 897558.07 | J374: =J13+J43+J73+J103+J133+J163+J193+J223+J253+J283+J313+J343 -> 33517.36 | K374: =J374/I374 -> 0.037342832 | L374: =L13+L43+L73+L103+L133+L163+L193+L223+L253+L283+L313+L343 -> 325876.4 | M374: =M13+M43+M73+M103+M133+M163+M193+M223+M253+M283+M313+M343 -> 308771.38 | N374: =N13+N43+N73+N103+N133+N163+N193+N223+N253+N283+N313+N343 -> 17105.02 | O374: =N374/M374 -> 0.055397038 | P374: =P13+P43+P73+P103+P133+P163+P193+P223+P253+P283+P313+P343 -> 24828.68 | Q374: =Q13+Q43+Q73+Q103+Q133+Q163+Q193+Q223+Q253+Q283+Q313+Q343 -> 23303.99 | R374: =R13+R43+R73+R103+R133+R163+R193+R223+R253+R283+R313+R343 -> 1524.69 | S374: =R374/Q374 -> 0.065426135 | T374: =T13+T43+T73+T103+T133+T163+T193+T223+T253+T283+T313+T343 -> 580370.35 | U374: =U13+U43+U73+U103+U133+U163+U193+U223+U253+U283+U313+U343 -> 553589.78 | V374: =V13+V43+V73+V103+V133+V163+V193+V223+V253+V283+V313+V343 -> 26780.57 | W374: =V374/U374 -> 0.0483762 | X374: =X13+X43+X73+X103+X133+X163+X193+X223+X253+X283+X313+X343 -> 385663 | Y374: =Y13+Y43+Y73+Y103+Y133+Y163+Y193+Y223+Y253+Y283+Y313+Y343 -> 363921.95 | Z374: =Z13+Z43+Z73+Z103+Z133+Z163+Z193+Z223+Z253+Z283+Z313+Z343 -> 21741.06 | AA374: =Z374/Y374 -> 0.059740997 | AB374: =AB13+AB43+AB73+AB103+AB133+AB163+AB193+AB223+AB253+AB283+AB313+AB343 -> 194707.35 | AC374: =AC13+AC43+AC73+AC103+AC133+AC163+AC193+AC223+AC253+AC283+AC313+AC343 -> 179981.47 | AD374: =AD13+AD43+AD73+AD103+AD133+AD163+AD193+AD223+AD253+AD283+AD313+AD343 -> 14725.88 | AE374: =AD374/AC374 -> 0.081818867
B375: India | C375: FX Conversion | D375: =D14+D44+D74+D104+D134+D164+D194+D224+D254+D284+D314+D344 -> 1.9300084e+08 | E375: =E14+E44+E74+E104+E134+E164+E194+E224+E254+E284+E314+E344 -> 1.8430578e+08 | F375: =F14+F44+F74+F104+F134+F164+F194+F224+F254+F284+F314+F344 -> 8695068.3 | G375: =F375/E375 -> 0.047177406 | H375: =H14+H44+H74+H104+H134+H164+H194+H224+H254+H284+H314+H344 -> 2026508.9 | I375: =I14+I44+I74+I104+I134+I164+I194+I224+I254+I284+I314+I344 -> 1920506.9 | J375: =J14+J44+J74+J104+J134+J164+J194+J224+J254+J284+J314+J344 -> 106001.98 | K375: =J375/I375 -> 0.055194793 | L375: =L14+L44+L74+L104+L134+L164+L194+L224+L254+L284+L314+L344 -> 567422.48 | M375: =M14+M44+M74+M104+M134+M164+M194+M224+M254+M284+M314+M344 -> 528703.89 | N375: =N14+N44+N74+N104+N134+N164+N194+N224+N254+N284+N314+N344 -> 38718.59 | O375: =N375/M375 -> 0.073233034 | P375: =P14+P44+P74+P104+P134+P164+P194+P224+P254+P284+P314+P344 -> 38600.17 | Q375: =Q14+Q44+Q74+Q104+Q134+Q164+Q194+Q224+Q254+Q284+Q314+Q344 -> 35633.54 | R375: =R14+R44+R74+R104+R134+R164+R194+R224+R254+R284+R314+R344 -> 2966.63 | S375: =R375/Q375 -> 0.083253867 | T375: =T14+T44+T74+T104+T134+T164+T194+T224+T254+T284+T314+T344 -> 1420486.2 | U375: =U14+U44+U74+U104+U134+U164+U194+U224+U254+U284+U314+U344 -> 1332265.8 | V375: =V14+V44+V74+V104+V134+V164+V194+V224+V254+V284+V314+V344 -> 88220.38 | W375: =V375/U375 -> 0.066218301 | X375: =X14+X44+X74+X104+X134+X164+X194+X224+X254+X284+X314+X344 -> 839556.63 | Y375: =Y14+Y44+Y74+Y104+Y134+Y164+Y194+Y224+Y254+Y284+Y314+Y344 -> 779484.35 | Z375: =Z14+Z44+Z74+Z104+Z134+Z164+Z194+Z224+Z254+Z284+Z314+Z344 -> 60072.26 | AA375: =Z375/Y375 -> 0.077066666 | AB375: =AB14+AB44+AB74+AB104+AB134+AB164+AB194+AB224+AB254+AB284+AB314+AB344 -> 580929.58 | AC375: =AC14+AC44+AC74+AC104+AC134+AC164+AC194+AC224+AC254+AC284+AC314+AC344 -> 527858.12 | AD375: =AD14+AD44+AD74+AD104+AD134+AD164+AD194+AD224+AD254+AD284+AD314+AD344 -> 53071.48 | AE375: =AD375/AC375 -> 0.10054118
B376: India | C376: Stablecoin Settlement | D376: =D15+D45+D75+D105+D135+D165+D195+D225+D255+D285+D315+D345 -> 2.9810112e+08 | E376: =E15+E45+E75+E105+E135+E165+E195+E225+E255+E285+E315+E345 -> 2.8950031e+08 | F376: =F15+F45+F75+F105+F135+F165+F195+F225+F255+F285+F315+F345 -> 8600812.3 | G376: =F376/E376 -> 0.029709164 | H376: =H15+H45+H75+H105+H135+H165+H195+H225+H255+H285+H315+H345 -> 1937657.3 | I376: =I15+I45+I75+I105+I135+I165+I195+I225+I255+I285+I315+I345 -> 1867189.7 | J376: =J15+J45+J75+J105+J135+J165+J195+J225+J255+J285+J315+J345 -> 70467.62 | K376: =J376/I376 -> 0.037739937 | L376: =L15+L45+L75+L105+L135+L165+L195+L225+L255+L285+L315+L345 -> 620050.33 | M376: =M15+M45+M75+M105+M135+M165+M195+M225+M255+M285+M315+M345 -> 587275.94 | N376: =N15+N45+N75+N105+N135+N165+N195+N225+N255+N285+N315+N345 -> 32774.39 | O376: =N376/M376 -> 0.05580748 | P376: =P15+P45+P75+P105+P135+P165+P195+P225+P255+P285+P315+P345 -> 59620.22 | Q376: =Q15+Q45+Q75+Q105+Q135+Q165+Q195+Q225+Q255+Q285+Q315+Q345 -> 55937.11 | R376: =R15+R45+R75+R105+R135+R165+R195+R225+R255+R285+R315+R345 -> 3683.11 | S376: =R376/Q376 -> 0.065843766 | T376: =T15+T45+T75+T105+T135+T165+T195+T225+T255+T285+T315+T345 -> 1257986.7 | U376: =U15+U45+U75+U105+U135+U165+U195+U225+U255+U285+U315+U345 -> 1199474.6 | V376: =V15+V45+V75+V105+V135+V165+V195+V225+V255+V285+V315+V345 -> 58512.15 | W376: =V376/U376 -> 0.048781484 | X376: =X15+X45+X75+X105+X135+X165+X195+X225+X255+X285+X315+X345 -> 802575.32 | Y376: =Y15+Y45+Y75+Y105+Y135+Y165+Y195+Y225+Y255+Y285+Y315+Y345 -> 756947.96 | Z376: =Z15+Z45+Z75+Z105+Z135+Z165+Z195+Z225+Z255+Z285+Z315+Z345 -> 45627.38 | AA376: =Z376/Y376 -> 0.060278094 | AB376: =AB15+AB45+AB75+AB105+AB135+AB165+AB195+AB225+AB255+AB285+AB315+AB345 -> 455411.42 | AC376: =AC15+AC45+AC75+AC105+AC135+AC165+AC195+AC225+AC255+AC285+AC315+AC345 -> 420857.96 | AD376: =AD15+AD45+AD75+AD105+AD135+AD165+AD195+AD225+AD255+AD285+AD315+AD345 -> 34553.47 | AE376: =AD376/AC376 -> 0.082102451
... B393: USA | C393: Virtual Accounts | D393: =D32+D62+D92+D122+D152+D182+D212+D242+D272+D302+D332+D362 -> 2.7845278e+08 | E393: =E32+E62+E92+E122+E152+E182+E212+E242+E272+E302+E332+E362 -> 2.7105924e+08 | F393: =F32+F62+F92+F122+F152+F182+F212+F242+F272+F302+F332+F362 -> 7393545.9 | G393: =F393/E393 -> 0.027276495 | H393: =H32+H62+H92+H122+H152+H182+H212+H242+H272+H302+H332+H362 -> 1253037.5 | I393: =I32+I62+I92+I122+I152+I182+I212+I242+I272+I302+I332+I362 -> 1210329.6 | J393: =J32+J62+J92+J122+J152+J182+J212+J242+J272+J302+J332+J362 -> 42707.98 | K393: =J393/I393 -> 0.035286241 | L393: =L32+L62+L92+L122+L152+L182+L212+L242+L272+L302+L332+L362 -> 275668.25 | M393: =M32+M62+M92+M122+M152+M182+M212+M242+M272+M302+M332+M362 -> 261716.72 | N393: =N32+N62+N92+N122+N152+N182+N212+N242+N272+N302+N332+N362 -> 13951.53 | O393: =N393/M393 -> 0.053307752 | P393: =P32+P62+P92+P122+P152+P182+P212+P242+P272+P302+P332+P362 -> 19491.69 | Q393: =Q32+Q62+Q92+Q122+Q152+Q182+Q212+Q242+Q272+Q302+Q332+Q362 -> 18330.98 | R393: =R32+R62+R92+R122+R152+R182+R212+R242+R272+R302+R332+R362 -> 1160.71 | S393: =R393/Q393 -> 0.063319582 | T393: =T32+T62+T92+T122+T152+T182+T212+T242+T272+T302+T332+T362 -> 957877.58 | U393: =U32+U62+U92+U122+U152+U182+U212+U242+U272+U302+U332+U362 -> 915490.9 | V393: =V32+V62+V92+V122+V152+V182+V212+V242+V272+V302+V332+V362 -> 42386.68 | W393: =V393/U393 -> 0.046299401 | X393: =X32+X62+X92+X122+X152+X182+X212+X242+X272+X302+X332+X362 -> 519419.5 | Y393: =Y32+Y62+Y92+Y122+Y152+Y182+Y212+Y242+Y272+Y302+Y332+Y362 -> 491442.94 | Z393: =Z32+Z62+Z92+Z122+Z152+Z182+Z212+Z242+Z272+Z302+Z332+Z362 -> 27976.57 | AA393: =Z393/Y393 -> 0.056927402 | AB393: =AB32+AB62+AB92+AB122+AB152+AB182+AB212+AB242+AB272+AB302+AB332+AB362 -> 438458.08 | AC393: =AC32+AC62+AC92+AC122+AC152+AC182+AC212+AC242+AC272+AC302+AC332+AC362 -> 405680.83 | AD393: =AD32+AD62+AD92+AD122+AD152+AD182+AD212+AD242+AD272+AD302+AD332+AD362 -> 32777.25 | AE393: =AD393/AC393 -> 0.080795659
A395: By Country | B395: Brazil | D395: =SUM(D364:D368) -> 1197664933 | E395: =SUM(E364:E368) -> 1.1545076e+09 | F395: =SUM(F364:F368) -> 43157331 | G395: =F395/E395 -> 0.037381591 | H395: =SUM(H364:H368) -> 8332492.3 | I395: =SUM(I364:I368) -> 7949976.4 | J395: =SUM(J364:J368) -> 382515.9 | K395: =J395/I395 -> 0.048115351 | L395: =SUM(L364:L368) -> 2459153.2 | M395: =SUM(M364:M368) -> 2306712.9 | N395: =SUM(N364:N368) -> 152440.37 | O395: =N395/M395 -> 0.066085542 | P395: =SUM(P364:P368) -> 215579.66 | Q395: =SUM(Q364:Q368) -> 200824.49 | R395: =SUM(R364:R368) -> 14755.17 | S395: =R395/Q395 -> 0.073472961 | T395: =SUM(T364:T368) -> 5657759.4 | U395: =SUM(U364:U368) -> 5341129.2 | V395: =SUM(V364:V368) -> 316630.17 | W395: =V395/U395 -> 0.059281503 | X395: =SUM(X364:X368) -> 3452479.9 | Y395: =SUM(Y364:Y368) -> 3225791.4 | Z395: =SUM(Z364:Z368) -> 226688.36 | AA395: =Z395/Y395 -> 0.070273719 | AB395: =SUM(AB364:AB368) -> 2205279.6 | AC395: =SUM(AC364:AC368) -> 2016860.7 | AD395: =SUM(AD364:AD368) -> 188418.87 | AE395: =AD395/AC395 -> 0.093421854
B396: Germany | D396: =SUM(D369:D373) -> 5.7902215e+08 | E396: =SUM(E369:E373) -> 5.6505068e+08 | F396: =SUM(F369:F373) -> 13971470 | G396: =F396/E396 -> 0.024726047 | H396: =SUM(H369:H373) -> 4028645.2 | I396: =SUM(I369:I373) -> 3890364.4 | J396: =SUM(J369:J373) -> 138280.84 | K396: =J396/I396 -> 0.035544445 | L396: =SUM(L369:L373) -> 1188942.6 | M396: =SUM(M369:M373) -> 1128503.8 | N396: =SUM(N369:N373) -> 60438.82 | O396: =N396/M396 -> 0.053556595 | P396: =SUM(P369:P373) -> 52112.04 | Q396: =SUM(Q369:Q373) -> 49125.5 | R396: =SUM(R369:R373) -> 2986.54 | S396: =R396/Q396 -> 0.060794089 | T396: =SUM(T369:T373) -> 2787590.6 | U396: =SUM(U369:U373) -> 2663402.7 | V396: =SUM(V369:V373) -> 124187.93 | W396: =V396/U396 -> 0.046627546 | X396: =SUM(X369:X373) -> 1669954.1 | Y396: =SUM(Y369:Y373) -> 1579062.4 | Z396: =SUM(Z369:Z373) -> 90891.59 | AA396: =Z396/Y396 -> 0.05756048 | AB396: =SUM(AB369:AB373) -> 1117636.5 | AC396: =SUM(AC369:AC373) -> 1034063.2 | AD396: =SUM(AD369:AD373) -> 83573.25 | AE396: =AD396/AC396 -> 0.08082025
B397: India | D397: =SUM(D374:D378) -> 8.1645138e+08 | E397: =SUM(E374:E378) -> 7.9086479e+08 | F397: =SUM(F374:F378) -> 25586584 | G397: =F397/E397 -> 0.032352666 | H397: =SUM(H374:H378) -> 5680125.8 | I397: =SUM(I374:I378) -> 5445401.1 | J397: =SUM(J374:J378) -> 234724.76 | K397: =J397/I397 -> 0.043105137 | L397: =SUM(L374:L378) -> 1676380.3 | M397: =SUM(M374:M378) -> 1579913.3 | N397: =SUM(N374:N378) -> 96466.98 | O397: =N397/M397 -> 0.0610584 | P397: =SUM(P374:P378) -> 163290.3 | Q397: =SUM(Q374:Q378) -> 152828.96 | R397: =SUM(R374:R378) -> 10461.34 | S397: =R397/Q397 -> 0.068451294 | T397: =SUM(T374:T378) -> 3840455.2 | U397: =SUM(U374:U378) -> 3642674.8 | V397: =SUM(V374:V378) -> 197780.38 | W397: =V397/U397 -> 0.05429537 | X397: =SUM(X374:X378) -> 2352953.6 | Y397: =SUM(Y374:Y378) -> 2208744.7 | Z397: =SUM(Z374:Z378) -> 144208.84 | AA397: =Z397/Y397 -> 0.065289953 | AB397: =SUM(AB374:AB378) -> 1487501.7 | AC397: =SUM(AC374:AC378) -> 1366634.5 | AD397: =SUM(AD374:AD378) -> 120867.17 | AE397: =AD397/AC397 -> 0.088441474
B398: Mexico | D398: =SUM(D379:D383) -> 9.689804e+08 | E398: =SUM(E379:E383) -> 9.4383987e+08 | F398: =SUM(F379:F383) -> 25140538 | G398: =F398/E398 -> 0.026636444 | H398: =SUM(H379:H383) -> 6741376.6 | I398: =SUM(I379:I383) -> 6498110.7 | J398: =SUM(J379:J383) -> 243265.88 | K398: =J398/I398 -> 0.037436401 | L398: =SUM(L379:L383) -> 1989579.3 | M398: =SUM(M379:M383) -> 1885107.9 | N398: =SUM(N379:N383) -> 104471.43 | O398: =N398/M398 -> 0.055419338 | P398: =SUM(P379:P383) -> 145347.06 | Q398: =SUM(Q379:Q383) -> 136768.44 | R398: =SUM(R379:R383) -> 8578.62 | S398: =R398/Q398 -> 0.062723681 | T398: =SUM(T379:T383) -> 4606450.2 | U398: =SUM(U379:U383) -> 4393045.9 | V398: =SUM(V379:V383) -> 213404.28 | W398: =V398/U398 -> 0.048577749 | X398: =SUM(X379:X383) -> 2792896.9 | Y398: =SUM(Y379:Y383) -> 2636093 | Z398: =SUM(Z379:Z383) -> 156803.79 | AA398: =Z398/Y398 -> 0.059483406 | AB398: =SUM(AB379:AB383) -> 1813553.3 | AC398: =SUM(AC379:AC383) -> 1674809 | AD398: =SUM(AD379:AD383) -> 138744.29 | AE398: =AD398/AC398 -> 0.082841856
B399: Singapore | D399: =SUM(D384:D388) -> 7.7482902e+08 | E399: =SUM(E384:E388) -> 7.5215284e+08 | F399: =SUM(F384:F388) -> 22676175 | G399: =F399/E399 -> 0.030148361 | H399: =SUM(H384:H388) -> 5390853.5 | I399: =SUM(I384:I388) -> 5179036.5 | J399: =SUM(J384:J388) -> 211817.06 | K399: =J399/I399 -> 0.040898932 | L399: =SUM(L384:L388) -> 1590977.2 | M399: =SUM(M384:M388) -> 1502402 | N399: =SUM(N384:N388) -> 88575.22 | O399: =N399/M399 -> 0.058955739 | P399: =SUM(P384:P388) -> 61986.31 | Q399: =SUM(Q384:Q388) -> 58136.84 | R399: =SUM(R384:R388) -> 3849.47 | S399: =R399/Q399 -> 0.066213953 | T399: =SUM(T384:T388) -> 3737890 | U399: =SUM(U384:U388) -> 3553278.2 | V399: =SUM(V384:V388) -> 184611.8 | W399: =V399/U399 -> 0.051955346 | X399: =SUM(X384:X388) -> 2234140.8 | Y399: =SUM(Y384:Y388) -> 2102219.1 | Z399: =SUM(Z384:Z388) -> 131921.66 | AA399: =Z399/Y399 -> 0.062753524 | AB399: =SUM(AB384:AB388) -> 1503749.2 | AC399: =SUM(AC384:AC388) -> 1384223.7 | AD399: =SUM(AD384:AD388) -> 119525.55 | AE399: =AD399/AC399 -> 0.086348437
B400: USA | D400: =SUM(D389:D393) -> 1.8818767e+09 | E400: =SUM(E389:E393) -> 1.818898e+09 | F400: =SUM(F389:F393) -> 62978714 | G400: =F400/E400 -> 0.034624654 | H400: =SUM(H389:H393) -> 13093294 | I400: =SUM(I389:I393) -> 12524986 | J400: =SUM(J389:J393) -> 568307.91 | K400: =J400/I400 -> 0.045373937 | L400: =SUM(L389:L393) -> 3864142.1 | M400: =SUM(M389:M393) -> 3633842.9 | N400: =SUM(N389:N393) -> 230299.2 | O400: =N400/M400 -> 0.063376213 | P400: =SUM(P389:P393) -> 131731.38 | Q400: =SUM(Q389:Q393) -> 123032.62 | R400: =SUM(R389:R393) -> 8698.76 | S400: =R400/Q400 -> 0.070702875 | T400: =SUM(T389:T393) -> 9097420.2 | U400: =SUM(U389:U393) -> 8611276.3 | V400: =SUM(V389:V393) -> 486143.83 | W400: =V400/U400 -> 0.056454329 | X400: =SUM(X389:X393) -> 5426861.2 | Y400: =SUM(Y389:Y393) -> 5084081.4 | Z400: =SUM(Z389:Z393) -> 342779.82 | AA400: =Z400/Y400 -> 0.067422173 | AB400: =SUM(AB389:AB393) -> 3670559 | AC400: =SUM(AC389:AC393) -> 3365602.7 | AD400: =SUM(AD389:AD393) -> 304956.25 | AE400: =AD400/AC400 -> 0.090609701
A402: By Product | C402: Cross-border Payouts | D402: =D364+D369+D374+D379+D384+D389 -> 9.4557542e+08 | E402: =E364+E369+E374+E379+E384+E389 -> 9.1843081e+08 | F402: =F364+F369+F374+F379+F384+F389 -> 27144610 | G402: =F402/E402 -> 0.029555422 | H402: =H364+H369+H374+H379+H384+H389 -> 7091815.7 | I402: =I364+I369+I374+I379+I384+I389 -> 6834997.9 | J402: =J364+J369+J374+J379+J384+J389 -> 256817.75 | K402: =J402/I402 -> 0.037573932 | L402: =L364+L369+L374+L379+L384+L389 -> 2482135.5 | M402: =M364+M369+M374+M379+M384+M389 -> 2351365.4 | N402: =N364+N369+N374+N379+N384+N389 -> 130770.11 | O402: =N402/M402 -> 0.055614543 | P402: =P364+P369+P374+P379+P384+P389 -> 117086.48 | Q402: =Q364+Q369+Q374+Q379+Q384+Q389 -> 109861.16 | R402: =R364+R369+R374+R379+R384+R389 -> 7225.32 | S402: =R402/Q402 -> 0.065767738 | T402: =T364+T369+T374+T379+T384+T389 -> 4492593.7 | U402: =U364+U369+U374+U379+U384+U389 -> 4284391.3 | V402: =V364+V369+V374+V379+V384+V389 -> 208202.42 | W402: =V402/U402 -> 0.048595566 | X402: =X364+X369+X374+X379+X384+X389 -> 2938549.3 | Y402: =Y364+Y369+Y374+Y379+Y384+Y389 -> 2772626 | Z402: =Z364+Z369+Z374+Z379+Z384+Z389 -> 165923.32 | AA402: =Z402/Y402 -> 0.059843383 | AB402: =AB364+AB369+AB374+AB379+AB384+AB389 -> 1554044.4 | AC402: =AC364+AC369+AC374+AC379+AC384+AC389 -> 1435941.1 | AD402: =AD364+AD369+AD374+AD379+AD384+AD389 -> 118103.29 | AE402: =AD402/AC402 -> 0.082248003
C403: FX Conversion | D403: =D365+D370+D375+D380+D385+D390 -> 1.470617e+09 | E403: =E365+E370+E375+E380+E385+E390 -> 1.4051138e+09 | F403: =F365+F370+F375+F380+F385+F390 -> 65503182 | G403: =F403/E403 -> 0.046617705 | H403: =H365+H370+H375+H380+H385+H390 -> 15441479 | I403: =I365+I370+I375+I380+I385+I390 -> 14641549 | J403: =J365+J370+J375+J380+J385+J390 -> 799929.07 | K403: =J403/I403 -> 0.054634181 | L403: =L365+L370+L375+L380+L385+L390 -> 4323614 | M403: =M365+M370+M375+M380+M385+M390 -> 4030701.4 | N403: =N365+N370+N375+N380+N385+N390 -> 292912.59 | O403: =N403/M403 -> 0.072670377 | P403: =P365+P370+P375+P380+P385+P390 -> 182082.1 | Q403: =Q365+Q370+Q375+Q380+Q385+Q390 -> 168124.37 | R403: =R365+R370+R375+R380+R385+R390 -> 13957.73 | S403: =R403/Q403 -> 0.083020266 | T403: =T365+T370+T375+T380+T385+T390 -> 10935782 | U403: =U365+U370+U375+U380+U385+U390 -> 10262068 | V403: =V365+V370+V375+V380+V385+V390 -> 673714.45 | W403: =V403/U403 -> 0.065650944 | X403: =X365+X370+X375+X380+X385+X390 -> 6399357.3 | Y403: =Y365+Y370+Y375+Y380+Y385+Y390 -> 5945207 | Z403: =Z365+Z370+Z375+Z380+Z385+Z390 -> 454150.22 | AA403: =Z403/Y403 -> 0.076389303 | AB403: =AB365+AB370+AB375+AB380+AB385+AB390 -> 4536425.2 | AC403: =AC365+AC370+AC375+AC380+AC385+AC390 -> 4123582.7 | AD403: =AD365+AD370+AD375+AD380+AD385+AD390 -> 412842.44 | AE403: =AD403/AC403 -> 0.10011741
C404: Stablecoin Settlement | D404: =D366+D371+D376+D381+D386+D391 -> 2.270051e+09 | E404: =E366+E371+E376+E381+E386+E391 -> 2.2043322e+09 | F404: =F366+F371+F376+F381+F386+F391 -> 65718863 | G404: =F404/E404 -> 0.029813503 | H404: =H366+H371+H376+H381+H386+H391 -> 14755332 | I404: =I366+I371+I376+I381+I386+I391 -> 14217385 | J404: =J366+J371+J376+J381+J386+J391 -> 537946.3 | K404: =J404/I404 -> 0.037837217 | L404: =L366+L371+L376+L381+L386+L391 -> 4721706.2 | M404: =M366+M371+M376+M381+M386+M391 -> 4471781.6 | N404: =N366+N371+N376+N381+N386+N391 -> 249924.52 | O404: =N404/M404 -> 0.05588925 | P404: =P366+P371+P376+P381+P386+P391 -> 281106.74 | Q404: =Q366+Q371+Q376+Q381+Q386+Q391 -> 263681.41 | R404: =R366+R371+R376+R381+R386+R391 -> 17425.33 | S404: =R404/Q404 -> 0.066084788 | T404: =T366+T371+T376+T381+T386+T391 -> 9752518.8 | U404: =U366+U371+U376+U381+U386+U391 -> 9298168.5 | V404: =V366+V371+V376+V381+V386+V391 -> 454350.35 | W404: =V404/U404 -> 0.0488645 | X404: =X366+X371+X376+X381+X386+X391 -> 6113878.5 | Y404: =Y366+Y371+Y376+Y381+Y386+Y391 -> 5766421.6 | Z404: =Z366+Z371+Z376+Z381+Z386+Z391 -> 347456.92 | AA404: =Z404/Y404 -> 0.060255206 | AB404: =AB366+AB371+AB376+AB381+AB386+AB391 -> 3638640.3 | AC404: =AC366+AC371+AC376+AC381+AC386+AC391 -> 3361777.6 | AD404: =AD366+AD371+AD376+AD381+AD386+AD391 -> 276862.78 | AE404: =AD404/AC404 -> 0.082356068
C405: Treasury Yield | D405: =D367+D372+D377+D382+D387+D392 -> 6.1230278e+08 | E405: =E367+E372+E377+E382+E387+E392 -> 5.9945496e+08 | F405: =F367+F372+F377+F382+F387+F392 -> 12847818 | G405: =F405/E405 -> 0.0214325 | H405: =H367+H372+H377+H382+H387+H392 -> 1836908.3 | I405: =I367+I372+I377+I382+I387+I392 -> 1784364 | J405: =J367+J372+J377+J382+J387+J392 -> 52544.36 | K405: =J405/I405 -> 0.029447109 | L405: =L367+L372+L377+L382+L387+L392 -> 330643.53 | M405: =M367+M372+M377+M382+M387+M392 -> 315656.41 | N405: =N367+N372+N377+N382+N387+N392 -> 14987.12 | O405: =N405/M405 -> 0.04747922 | P405: =P367+P372+P377+P382+P387+P392 -> 75812.34 | Q405: =Q367+Q372+Q377+Q382+Q387+Q392 -> 71665.98 | R405: =R367+R372+R377+R382+R387+R392 -> 4146.36 | S405: =R405/Q405 -> 0.05785674 | T405: =T367+T372+T377+T382+T387+T392 -> 1430452.5 | U405: =U367+U372+U377+U382+U387+U392 -> 1374843.2 | V405: =V367+V372+V377+V382+V387+V392 -> 55609.22 | W405: =V405/U405 -> 0.04044768 | X405: =X367+X372+X377+X382+X387+X392 -> 761210.92 | Y405: =Y367+Y372+Y377+Y382+Y387+Y392 -> 724155.96 | Z405: =Z367+Z372+Z377+Z382+Z387+Z392 -> 37054.93 | AA405: =Z405/Y405 -> 0.05116982 | AB405: =AB367+AB372+AB377+AB382+AB387+AB392 -> 669241.55 | AC405: =AC367+AC372+AC377+AC382+AC387+AC392 -> 622640.57 | AD405: =AD367+AD372+AD377+AD382+AD387+AD392 -> 46600.97 | AE405: =AD405/AC405 -> 0.074844095
C406: Virtual Accounts | D406: =D368+D373+D378+D383+D388+D393 -> 9.202784e+08 | E406: =E368+E373+E378+E383+E388+E393 -> 8.9798206e+08 | F406: =F368+F373+F378+F383+F388+F393 -> 22296338 | G406: =F406/E406 -> 0.024829381 | H406: =H368+H373+H378+H383+H388+H393 -> 4141252.8 | I406: =I368+I373+I378+I383+I388+I393 -> 4009577.9 | J406: =J368+J373+J378+J383+J388+J393 -> 131674.87 | K406: =J406/I406 -> 0.032840083 | L406: =L368+L373+L378+L383+L388+L393 -> 911075.6 | M406: =M368+M373+M378+M383+M388+M393 -> 866977.92 | N406: =N368+N373+N378+N383+N388+N393 -> 44097.68 | O406: =N406/M406 -> 0.050863671 | P406: =P368+P373+P378+P383+P388+P393 -> 113959.09 | Q406: =Q368+Q373+Q378+Q383+Q388+Q393 -> 107383.93 | R406: =R368+R373+R378+R383+R388+R393 -> 6575.16 | S406: =R406/Q406 -> 0.061230391 | T406: =T368+T373+T378+T383+T388+T393 -> 3116218.1 | U406: =U368+U373+U378+U383+U388+U393 -> 2985336.2 | V406: =V368+V373+V378+V383+V388+V393 -> 130881.95 | W406: =V406/U406 -> 0.043841612 | X406: =X368+X373+X378+X383+X388+X393 -> 1716290.4 | Y406: =Y368+Y373+Y378+Y383+Y388+Y393 -> 1627581.6 | Z406: =Z368+Z373+Z378+Z383+Z388+Z393 -> 88708.67 | AA406: =Z406/Y406 -> 0.054503361 | AB406: =AB368+AB373+AB378+AB383+AB388+AB393 -> 1399927.8 | AC406: =AC368+AC373+AC378+AC383+AC388+AC393 -> 1298251.9 | AD406: =AD368+AD373+AD378+AD383+AD388+AD393 -> 101675.9 | AE406: =AD406/AC406 -> 0.078317546
...

Sheet Assumption-Base
A1: Growth and Margin Assumptions | B1: FY 26 | C1: BASE - key TPV, take rate, COGS, Loss rate, OPEX assumptions aligned with all Sr. leaders including country/product SVPs
A2: Country | B2: Product | C2: TPV YOY Growth | D2: Take Rate | E2: COGS % Revenue | F2: Loss Rate % TPV | G2: OPEX % Revenue | H2: Notes
A3: Brazil | B3: Cross-border Payouts | C3: 0.2 | D3: 0.0075 | E3: 0.35 | F3: 7e-05 | G3: 0.4
A4: Brazil | B4: FX Conversion | C4: 0.2 | D4: 0.0105 | E4: 0.28 | F4: 7e-05 | G4: 0.4
A5: Brazil | B5: Stablecoin Settlement | C5: 0.4 | D5: 0.0065 | E5: 0.32 | F5: 7e-05 | G5: 0.4
A6: Brazil | B6: Treasury Yield | C6: 0.2 | D6: 0.003 | E6: 0.18 | F6: 7e-05 | G6: 0.4
A7: Brazil | B7: Virtual Accounts | C7: 0.2 | D7: 0.0045 | E7: 0.22 | F7: 7e-05 | G7: 0.4
A8: Germany | B8: Cross-border Payouts | C8: 0.06 | D8: 0.0075 | E8: 0.35 | F8: 0.00015 | G8: 0.4
A9: Germany | B9: FX Conversion | C9: 0.06 | D9: 0.0105 | E9: 0.28 | F9: 0.00015 | G9: 0.4
A10: Germany | B10: Stablecoin Settlement | C10: 0.12 | D10: 0.0065 | E10: 0.32 | F10: 0.00015 | G10: 0.4
A11: Germany | B11: Treasury Yield | C11: 0.06 | D11: 0.003 | E11: 0.18 | F11: 0.00015 | G11: 0.4
A12: Germany | B12: Virtual Accounts | C12: 0.06 | D12: 0.0045 | E12: 0.22 | F12: 0.00015 | G12: 0.4
A13: India | B13: Cross-border Payouts | C13: 0.12 | D13: 0.0075 | E13: 0.35 | F13: 0.00018 | G13: 0.4
A14: India | B14: FX Conversion | C14: 0.12 | D14: 0.0105 | E14: 0.28 | F14: 0.00018 | G14: 0.4
... A32: USA | B32: Virtual Accounts | C32: 0.1 | D32: 0.0045 | E32: 0.22 | F32: 0.0002 | G32: 0.4
A34: Blue text on yellow = editable input assumptions. Change these cells and the forecast, comparison and summary tabs update.

Sheet Assumption-Best
A1: Growth and Margin Assumptions | B1: FY 26 | C1: BEST - key TPV, take rate, COGS, Loss rate, OPEX assumptions aligned with all Sr. leaders including country/product SVPs
A2: Country | B2: Product | C2: TPV YOY Growth | D2: Take Rate | E2: COGS % Revenue | F2: Loss Rate % TPV | G2: OPEX % Revenue | H2: Notes
A3: Brazil | B3: Cross-border Payouts | C3: =2*'Assumption-Base'!C3 -> 0.4 | D3: 0.0075 | E3: 0.35 | F3: 7e-05 | G3: 0.35
A4: Brazil | B4: FX Conversion | C4: =2*'Assumption-Base'!C4 -> 0.4 | D4: 0.0105 | E4: 0.28 | F4: 7e-05 | G4: 0.35
A5: Brazil | B5: Stablecoin Settlement | C5: =2*'Assumption-Base'!C5 -> 0.8 | D5: 0.0065 | E5: 0.32 | F5: 7e-05 | G5: 0.35
A6: Brazil | B6: Treasury Yield | C6: =2*'Assumption-Base'!C6 -> 0.4 | D6: 0.003 | E6: 0.18 | F6: 7e-05 | G6: 0.35
A7: Brazil | B7: Virtual Accounts | C7: =2*'Assumption-Base'!C7 -> 0.4 | D7: 0.0045 | E7: 0.22 | F7: 7e-05 | G7: 0.35
A8: Germany | B8: Cross-border Payouts | C8: =2*'Assumption-Base'!C8 -> 0.12 | D8: 0.0075 | E8: 0.35 | F8: 0.00015 | G8: 0.35
A9: Germany | B9: FX Conversion | C9: =2*'Assumption-Base'!C9 -> 0.12 | D9: 0.0105 | E9: 0.28 | F9: 0.00015 | G9: 0.35
A10: Germany | B10: Stablecoin Settlement | C10: =2*'Assumption-Base'!C10 -> 0.24 | D10: 0.0065 | E10: 0.32 | F10: 0.00015 | G10: 0.35
A11: Germany | B11: Treasury Yield | C11: =2*'Assumption-Base'!C11 -> 0.12 | D11: 0.003 | E11: 0.18 | F11: 0.00015 | G11: 0.35
A12: Germany | B12: Virtual Accounts | C12: =2*'Assumption-Base'!C12 -> 0.12 | D12: 0.0045 | E12: 0.22 | F12: 0.00015 | G12: 0.35
A13: India | B13: Cross-border Payouts | C13: =2*'Assumption-Base'!C13 -> 0.24 | D13: 0.0075 | E13: 0.35 | F13: 0.00018 | G13: 0.35
A14: India | B14: FX Conversion | C14: =2*'Assumption-Base'!C14 -> 0.24 | D14: 0.0105 | E14: 0.28 | F14: 0.00018 | G14: 0.35
... A32: USA | B32: Virtual Accounts | C32: =2*'Assumption-Base'!C32 -> 0.2 | D32: 0.0045 | E32: 0.22 | F32: 0.0002 | G32: 0.35
A34: Blue text on yellow = editable input assumptions. Change these cells and the forecast, comparison and summary tabs update.

Sheet Assumption-Worst
A1: Growth and Margin Assumptions | B1: FY 26 | C1: WORST - key TPV, take rate, COGS, Loss rate, OPEX assumptions aligned with all Sr. leaders including country/product SVPs
A2: Country | B2: Product | C2: TPV YOY Growth | D2: Take Rate | E2: COGS % Revenue | F2: Loss Rate % TPV | G2: OPEX % Revenue | H2: Notes
A3: Brazil | B3: Cross-border Payouts | C3: =0.5*'Assumption-Base'!C3 -> 0.1 | D3: 0.0075 | E3: 0.35 | F3: 7e-05 | G3: 0.45
A4: Brazil | B4: FX Conversion | C4: =0.5*'Assumption-Base'!C4 -> 0.1 | D4: 0.0105 | E4: 0.28 | F4: 7e-05 | G4: 0.45
A5: Brazil | B5: Stablecoin Settlement | C5: =0.5*'Assumption-Base'!C5 -> 0.2 | D5: 0.0065 | E5: 0.32 | F5: 7e-05 | G5: 0.45
A6: Brazil | B6: Treasury Yield | C6: =0.5*'Assumption-Base'!C6 -> 0.1 | D6: 0.003 | E6: 0.18 | F6: 7e-05 | G6: 0.45
A7: Brazil | B7: Virtual Accounts | C7: =0.5*'Assumption-Base'!C7 -> 0.1 | D7: 0.0045 | E7: 0.22 | F7: 7e-05 | G7: 0.45
A8: Germany | B8: Cross-border Payouts | C8: =0.5*'Assumption-Base'!C8 -> 0.03 | D8: 0.0075 | E8: 0.35 | F8: 0.00015 | G8: 0.45
A9: Germany | B9: FX Conversion | C9: =0.5*'Assumption-Base'!C9 -> 0.03 | D9: 0.0105 | E9: 0.28 | F9: 0.00015 | G9: 0.45
A10: Germany | B10: Stablecoin Settlement | C10: =0.5*'Assumption-Base'!C10 -> 0.06 | D10: 0.0065 | E10: 0.32 | F10: 0.00015 | G10: 0.45
A11: Germany | B11: Treasury Yield | C11: =0.5*'Assumption-Base'!C11 -> 0.03 | D11: 0.003 | E11: 0.18 | F11: 0.00015 | G11: 0.45
A12: Germany | B12: Virtual Accounts | C12: =0.5*'Assumption-Base'!C12 -> 0.03 | D12: 0.0045 | E12: 0.22 | F12: 0.00015 | G12: 0.45
A13: India | B13: Cross-border Payouts | C13: =0.5*'Assumption-Base'!C13 -> 0.06 | D13: 0.0075 | E13: 0.35 | F13: 0.00018 | G13: 0.45
A14: India | B14: FX Conversion | C14: =0.5*'Assumption-Base'!C14 -> 0.06 | D14: 0.0105 | E14: 0.28 | F14: 0.00018 | G14: 0.45
... A32: USA | B32: Virtual Accounts | C32: =0.5*'Assumption-Base'!C32 -> 0.05 | D32: 0.0045 | E32: 0.22 | F32: 0.0002 | G32: 0.45
A34: Blue text on yellow = editable input assumptions. Change these cells and the forecast, comparison and summary tabs update.

Sheet Variance
A1: FY2025 Actual vs Budget: Total Company
A3: Concept | B3: Actual | C3: Budget | D3: Variance ($) | E3: Variance (%) | F3: Result
A4: TPV | B4: ='2025 actual v budget'!D408 -> 6.2188246e+09 | C4: ='2025 actual v budget'!E408 -> 6.0253138e+09 | D4: =B4-C4 -> 1.9351081e+08 | E4: =D4/C4 -> 0.032116304 | F4: =IF(D4>=0,"Favorable","Unfavorable") -> Favorable
A5: Revenue | B5: ='2025 actual v budget'!H408 -> 43266787 | C5: ='2025 actual v budget'!I408 -> 41487875 | D5: =B5-C5 -> 1778912.4 | E5: =D5/C5 -> 0.042877886 | F5: =IF(D5>=0,"Favorable","Unfavorable") -> Favorable
A6: COGS | B6: ='2025 actual v budget'!L408 -> 12769175 | C6: ='2025 actual v budget'!M408 -> 12036483 | D6: =B6-C6 -> 732692.02 | E6: =D6/C6 -> 0.060872602 | F6: =IF(D6<=0,"Favorable","Unfavorable") -> Unfavorable
A7: Loss Provision | B7: ='2025 actual v budget'!P408 -> 770046.75 | C7: ='2025 actual v budget'!Q408 -> 720716.85 | D7: =B7-C7 -> 49329.9 | E7: =D7/C7 -> 0.068445604 | F7: =IF(D7<=0,"Favorable","Unfavorable") -> Unfavorable
A8: Gross Profit | B8: ='2025 actual v budget'!T408 -> 29727566 | C8: ='2025 actual v budget'!U408 -> 28204807 | D8: =B8-C8 -> 1522758.4 | E8: =D8/C8 -> 0.053989321 | F8: =IF(D8>=0,"Favorable","Unfavorable") -> Favorable
A9: OPEX | B9: ='2025 actual v budget'!X408 -> 17929286 | C9: ='2025 actual v budget'!Y408 -> 16835992 | D9: =B9-C9 -> 1093294.2 | E9: =D9/C9 -> 0.064937916 | F9: =IF(D9<=0,"Favorable","Unfavorable") -> Unfavorable
A10: Operating Profit | B10: ='2025 actual v budget'!AB408 -> 11798279 | C10: ='2025 actual v budget'!AC408 -> 10842194 | D10: =B10-C10 -> 956085.37 | E10: =D10/C10 -> 0.088181911 | F10: =IF(D10>=0,"Favorable","Unfavorable") -> Favorable
A12: Check: Budget Gross Profit rebuilt | C12: =C5-C6-C7 -> 28730675 | D12: =C12-C8 -> 525867.93
A14: By Country
B15: Country | D15: Actual_TPV_USD | E15: Budget_TPV_USD | F15: TPV_Var_$ | G15: TPV_Var_% | H15: Actual_Revenue_USD | I15: Budget_Revenue_USD | J15: Revenue_Var_$ | K15: Revenue_Var_% | L15: Actual_COGS_USD | M15: Budget_COGS_USD | N15: COGS_Var_$ | O15: COGS_Var_% | P15: Actual_Loss_Provision_USD | Q15: Budget_Loss_Provision_USD | R15: Loss_Provision_Var_$ | S15: Loss_Provision_Var_% | T15: Actual_Gross_Profit_USD | U15: Budget_Gross_Profit_USD | V15: Gross_Profit_Var_$ | W15: Gross_Profit_Var_% | X15: Actual_Operating_Expense_USD | Y15: Budget_Operating_Expense_USD | Z15: Opex_Var_$ | AA15: Opex_Var_% | AB15: Actual_Operating_Profit_USD | AC15: Budget_Operating_Profit_USD | AD15: Operating_Profit_Var_$ | AE15: Operating_Profit_Var_%
B16: ='2025 actual v budget'!B395 -> Brazil | D16: ='2025 actual v budget'!D395 -> 1197664933 | E16: ='2025 actual v budget'!E395 -> 1.1545076e+09 | F16: ='2025 actual v budget'!F395 -> 43157331 | G16: ='2025 actual v budget'!G395 -> 0.037381591 | H16: ='2025 actual v budget'!H395 -> 8332492.3 | I16: ='2025 actual v budget'!I395 -> 7949976.4 | J16: ='2025 actual v budget'!J395 -> 382515.9 | K16: ='2025 actual v budget'!K395 -> 0.048115351 | ... AE16: ='2025 actual v budget'!AE395 -> 0.093421854
B17: ='2025 actual v budget'!B396 -> Germany | D17: ='2025 actual v budget'!D396 -> 5.7902215e+08 | E17: ='2025 actual v budget'!E396 -> 5.6505068e+08 | F17: ='2025 actual v budget'!F396 -> 13971470 | G17: ='2025 actual v budget'!G396 -> 0.024726047 | H17: ='2025 actual v budget'!H396 -> 4028645.2 | I17: ='2025 actual v budget'!I396 -> 3890364.4 | J17: ='2025 actual v budget'!J396 -> 138280.84 | K17: ='2025 actual v budget'!K396 -> 0.035544445 | ... AE17: ='2025 actual v budget'!AE396 -> 0.08082025
B18: ='2025 actual v budget'!B397 -> India | D18: ='2025 actual v budget'!D397 -> 8.1645138e+08 | E18: ='2025 actual v budget'!E397 -> 7.9086479e+08 | F18: ='2025 actual v budget'!F397 -> 25586584 | G18: ='2025 actual v budget'!G397 -> 0.032352666 | H18: ='2025 actual v budget'!H397 -> 5680125.8 | I18: ='2025 actual v budget'!I397 -> 5445401.1 | J18: ='2025 actual v budget'!J397 -> 234724.76 | K18: ='2025 actual v budget'!K397 -> 0.043105137 | ... AE18: ='2025 actual v budget'!AE397 -> 0.088441474
B19: ='2025 actual v budget'!B398 -> Mexico | D19: ='2025 actual v budget'!D398 -> 9.689804e+08 | E19: ='2025 actual v budget'!E398 -> 9.4383987e+08 | F19: ='2025 actual v budget'!F398 -> 25140538 | G19: ='2025 actual v budget'!G398 -> 0.026636444 | H19: ='2025 actual v budget'!H398 -> 6741376.6 | I19: ='2025 actual v budget'!I398 -> 6498110.7 | J19: ='2025 actual v budget'!J398 -> 243265.88 | K19: ='2025 actual v budget'!K398 -> 0.037436401 | ... AE19: ='2025 actual v budget'!AE398 -> 0.082841856
B20: ='2025 actual v budget'!B399 -> Singapore | D20: ='2025 actual v budget'!D399 -> 7.7482902e+08 | E20: ='2025 actual v budget'!E399 -> 7.5215284e+08 | F20: ='2025 actual v budget'!F399 -> 22676175 | G20: ='2025 actual v budget'!G399 -> 0.030148361 | H20: ='2025 actual v budget'!H399 -> 5390853.5 | I20: ='2025 actual v budget'!I399 -> 5179036.5 | J20: ='2025 actual v budget'!J399 -> 211817.06 | K20: ='2025 actual v budget'!K399 -> 0.040898932 | ... AE20: ='2025 actual v budget'!AE399 -> 0.086348437
B21: ='2025 actual v budget'!B400 -> USA | D21: ='2025 actual v budget'!D400 -> 1.8818767e+09 | E21: ='2025 actual v budget'!E400 -> 1.818898e+09 | F21: ='2025 actual v budget'!F400 -> 62978714 | G21: ='2025 actual v budget'!G400 -> 0.034624654 | H21: ='2025 actual v budget'!H400 -> 13093294 | I21: ='2025 actual v budget'!I400 -> 12524986 | J21: ='2025 actual v budget'!J400 -> 568307.91 | K21: ='2025 actual v budget'!K400 -> 0.045373937 | ... AE21: ='2025 actual v budget'!AE400 -> 0.090609701
A24: By Product
B25: Product | D25: Actual_TPV_USD | E25: Budget_TPV_USD | F25: TPV_Var_$ | G25: TPV_Var_% | H25: Actual_Revenue_USD | I25: Budget_Revenue_USD | J25: Revenue_Var_$ | K25: Revenue_Var_% | L25: Actual_COGS_USD | M25: Budget_COGS_USD | N25: COGS_Var_$ | O25: COGS_Var_% | P25: Actual_Loss_Provision_USD | Q25: Budget_Loss_Provision_USD | R25: Loss_Provision_Var_$ | S25: Loss_Provision_Var_% | T25: Actual_Gross_Profit_USD | U25: Budget_Gross_Profit_USD | V25: Gross_Profit_Var_$ | W25: Gross_Profit_Var_% | X25: Actual_Operating_Expense_USD | Y25: Budget_Operating_Expense_USD | Z25: Opex_Var_$ | AA25: Opex_Var_% | AB25: Actual_Operating_Profit_USD | AC25: Budget_Operating_Profit_USD | AD25: Operating_Profit_Var_$ | AE25: Operating_Profit_Var_%
